<?xml version="1.0"?>

<robot name="robot_arm">
  <link name="world"/>
  <link name="arm_base">
    <inertial>
      <origin
        xyz="7.7128E-09 -0.063005 -3.01969999961422E-08"
        rpy="0 0 0" />
      <mass
        value="1.6004" />
      <inertia
        ixx="0.00552196561445819"
        ixy="7.9550614501301E-10"
        ixz="-1.34378458924839E-09"
        iyy="0.00352397447953875"
        iyz="-1.10071809773382E-08"
        izz="0.00553739792746489" />
    </inertial>
    <visual>
      <origin
        xyz="0 0 0"
        rpy="0 0 0" />
      <geometry>
        <mesh filename="package://mobile_manipulator_body/meshes/arm_base.stl" />
      </geometry>
      <material
        name="">
        <color
          rgba="0.79216 0.81961 0.93333 1" />
      </material>
    </visual>
    <collision>
      <origin
        xyz="0 0 0"
        rpy="0 0 0" />
      <geometry>
        <mesh filename="package://mobile_manipulator_body/meshes/arm_base.stl" />
      </geometry>
    </collision>
</link>

<link
    name="bicep">
    <inertial>
      <origin
        xyz="0.12821 3.5589E-06 0.052492"
        rpy="0 0 0" />
      <mass
        value="1.1198" />
      <inertia
        ixx="0.0012474"
        ixy="-5.4004E-07"
        ixz="-0.0013148"
        iyy="0.0072923"
        iyz="-1.8586E-07"
        izz="0.0068178" />
    </inertial>
    <visual>
      <origin
        xyz="0 0 0"
        rpy="0 -1.5708 0" />
      <geometry>
        <mesh filename="package://mobile_manipulator_body/meshes/bicep.stl" />
      </geometry>
      <material
        name="">
        <color
          rgba="0.79216 0.81961 0.93333 1" />
      </material>
    </visual>
    <collision>
      <origin
        xyz="0 0 0"
        rpy="0 -1.5708 0" />
      <geometry>
        <mesh filename="package://mobile_manipulator_body/meshes/bicep.stl" />
      </geometry>
    </collision>
  </link>


  <link
    name="bottom_wrist">
    <inertial>
      <origin
        xyz="-9.1053E-08 -0.069257 -1.86629999995759E-07"
        rpy="0 0 0" />
      <mass
        value="0.27721" />
      <inertia
        ixx="0.00104290750143942"
        ixy="4.37155302268076E-09"
        ixz="-2.45049603914627E-09"
        iyy="0.000380518373895034"
        iyz="-7.56009835172156E-09"
        izz="0.00106006525067445" />
    </inertial>
    <visual>
      <origin
        xyz="0 0 0.13522"
        rpy="3.14 0 1.5708" />
      <geometry>
        <mesh filename="package://mobile_manipulator_body/meshes/wrist.stl" />
      </geometry>
      <material
        name="">
        <color
          rgba="0.79216 0.81961 0.93333 1" />
      </material>
    </visual>
    <collision>
      <origin
        xyz="0 0 0.13522"
        rpy="3.14 0 1.5708" />
      <geometry>
        <mesh filename="package://mobile_manipulator_body/meshes/wrist.stl" />
      </geometry>
    </collision>
  </link>

 <link
    name="elbow">
    <inertial>
      <origin
        xyz="-0.11109 1.1476E-08 0.046469"
        rpy="0 0 0" />
      <mass
        value="0.84845" />
      <inertia
        ixx="0.00079656"
        ixy="-7.8011E-10"
        ixz="0.00053616"
        iyy="0.003576"
        iyz="4.6326E-10"
        izz="0.0033698" />
    </inertial>
    <visual>
      <origin
        xyz="0.0 0.05163 0.20994"
        rpy="0 -1.5708 0" />
      <geometry>
        <mesh filename="package://mobile_manipulator_body/meshes/elbow.stl" />
      </geometry>
      <material
        name="">
        <color
          rgba="0.79216 0.81961 0.93333 1" />
      </material>
    </visual>
    <collision>
      <origin
        xyz="0.0 0.05163 0.20994"
        rpy="0 -1.5708 0" />
      <geometry>
        <mesh filename="package://mobile_manipulator_body/meshes/elbow.stl" />
      </geometry>
    </collision>
  </link>

<link
    name="top_wrist">
    <inertial>
      <origin
        xyz="-9.1053E-08 -0.069257 -1.86629999995759E-07"
        rpy="0 0 0" />
      <mass
        value="0.27721" />
      <inertia
        ixx="0.00104290750143942"
        ixy="4.37155302268076E-09"
        ixz="-2.45049603914627E-09"
        iyy="0.000380518373895034"
        iyz="-7.56009835172156E-09"
        izz="0.00106006525067445" />
    </inertial>
    <visual>
      <origin
        xyz="0 0 0.13522"
        rpy="3.14 0 1.5708" />
      <geometry>
        <mesh filename="package://mobile_manipulator_body/meshes/wrist.stl" />
      </geometry>
      <material
        name="">
        <color
          rgba="0.79216 0.81961 0.93333 1" />
      </material>
    </visual>
    <collision>
      <origin
        xyz="0 0 0.13522"
        rpy="3.14 0 1.5708" />
      <geometry>
        <mesh filename="package://mobile_manipulator_body/meshes/wrist.stl" />
      </geometry>
    </collision>
  </link>
  
<!--##################### end_effector #####################-->
    <link name="griper_link">
      <visual>
        <origin xyz="0 0 0" rpy="0 0 0"/>
        <geometry>
          <mesh filename="package://mobile_manipulator_body/meshes/visual/wide_two_finger_gripper_actuator.stl"
              scale="1 1 1"/>
        </geometry>
        <material name="red"/>
      </visual>

      <collision>
        <origin xyz="0 0 0" rpy="0 0 0"/>
        <geometry>
          <mesh filename="package://mobile_manipulator_body/meshes/collision/wide_two_finger_gripper_actuator.stl"
              scale="1 1 1"/>
        </geometry>
      </collision>

      <inertial>
        <mass value="0.121"/>
        <origin xyz="1.08E-04 -1.03E-03 2.08E-02" rpy="0 0 0"/>
        <inertia ixx="3.20E-05" ixy="-9.45E-08" ixz="2.61E-07"
          iyy="4.14E-05" iyz="3.88E-07"
          izz="4.29E-05"/>
      </inertial>
    </link>

    <link name="finger_a_link">
      <visual>
        <origin xyz="0 0 0" rpy="1.570795 0 0"/>
        <geometry>
          <mesh filename="package://mobile_manipulator_body/meshes/visual/wide_two_finger_gripper_finger_a.stl"
              scale="1 1 1"/>
        </geometry>
        <material name="red"/>
      </visual>

      <collision>
        <origin xyz="0 0 0" rpy="1.570795 0 0"/>
        <geometry>
          <mesh filename="package://mobile_manipulator_body/meshes/collision/wide_two_finger_gripper_finger_a.stl"
              scale="1 1 1"/>
        </geometry>
      </collision>

      <inertial>
        <mass value="0.0158"/>
        <origin xyz="-2.65E-03 3.54E-03 2.69E-02" rpy="1.570795 0 0"/>
        <inertia ixx="1.01E-05" ixy="-1.97E-07" ixz="-9.89E-08"
        iyy="4.95E-06" iyz="5.37E-07"
        izz="6.24E-06"/>
      </inertial>
    </link>

    <link name="finger_b_link">
      <visual>
        <origin xyz="0 0 0" rpy="1.570795 0 0"/>
        <geometry>
          <mesh filename="package://mobile_manipulator_body/meshes/visual/wide_two_finger_gripper_finger_b.stl"
              scale="1 1 1"/>
        </geometry>
        <material name="red"/>
      </visual>

      <collision>
        <origin xyz="0 0 0" rpy="1.57095 0 0"/>
        <geometry>
          <mesh filename="package://mobile_manipulator_body/meshes/collision/wide_two_finger_gripper_finger_b.stl"
              scale="1 1 1"/>
        </geometry>
      </collision>

      <inertial>
        <mass value="0.0139"/>
        <origin xyz="3.01E-03 2.85E-03 3.09E-02" rpy="1.57095 0 0"/>
        <inertia ixx="7.48E-06" ixy="3.61E-07" ixz="6.34E-08"
        iyy="4.09E-06" iyz="2.28E-07"
        izz="4.37E-06"/>
      </inertial>
    </link>

<!--################## end_effector_joint #################-->
    <joint name="griper_joint" type="fixed">
        <parent link="top_wrist"/>
        <child  link="griper_link"/>
        <origin xyz="0 0 0.13522" rpy="0 0 0"/>
    </joint>

    <joint name="finger_a_joint" type="revolute">
      <origin xyz="-0.012 0.0 0.024" rpy="0 0 0"/>
      <axis xyz="0 -1 0"/>
      <limit effort="4.0" velocity="4.81710873" lower="0.0046" upper="1.62601"/>
      <parent link="griper_link"/>
      <child link="finger_a_link"/>
      <dynamics damping="1.0e-6" friction="8.0e-1"/>
    </joint>

    <joint name="finger_b_joint" type="revolute">
      <origin xyz="0.012 0.0 0.024" rpy="0 0 0"/>
      <axis xyz="0 1 0"/>
      <limit effort="4.0" velocity="4.81710873" lower="0.0046" upper="1.62601"/>
      <parent link="griper_link"/>
      <child link="finger_b_link"/>
      <mimic joint="finger_a_joint"/>
      <dynamics damping="1.0e-6" friction="8.0e-1"/>
    </joint>


<!-- for gazebo -->
    <transmission name="finger_a_joint_trans">
      <provideFeedback>true</provideFeedback>
      <implicitSpringDamper>0</implicitSpringDamper>
      <motorTorqueConstant>0.418</motorTorqueConstant>
      <type>transmission_interface/SimpleTransmission</type>
      <joint name="finger_a_joint">
          <hardwareInterface>hardware_interface/EffortJointInterface</hardwareInterface>
      </joint>
      <actuator name="finger_a_joint_motor">
          <hardwareInterface>hardware_interface/EffortJointInterface</hardwareInterface>
        <mechanicalReduction>1</mechanicalReduction>
      </actuator>
    </transmission>
    
        <!-- For gazebo simulation -->
    <gazebo>
      <plugin name="gripper_mimic_joint" filename="libroboticsgroup_upatras_gazebo_mimic_joint_plugin.so">
        <joint>finger_a_joint</joint>
        <mimicJoint>finger_b_joint</mimicJoint>
        <multiplier>1</multiplier>
      </plugin>
    </gazebo>

    <gazebo reference="griper_link">
      <material>Gazebo/Red</material>
    </gazebo>
    <gazebo reference="finger_a_link">
      <mu1>0.8</mu1>
      <mu2>0.8</mu2>
      <material>Gazebo/Red</material>
    </gazebo>
    <gazebo reference="finger_b_link">
      <mu1>0.8</mu1>
      <mu2>0.8</mu2>
      <material>Gazebo/Red</material>
    </gazebo>

<!--#################### camra ########################-->
    <link name="camera_link">
        <!-- Inertial for gazebo to take it into account, Put 1gr weight -->
        <inertial>
            <origin xyz="0 0 0" rpy="0 0 0"/>
            <mass value="0.001" />
            <inertia ixx="9.1875e-09" ixy="0.0" ixz="0.0" iyy="9.1875e-09" iyz="0.0" izz="1.378125e-08"/>
        </inertial>
		<visual>
            <origin rpy="0.0 0 0" xyz="0 0 0"/>
            <geometry>
                <box size="0.0005 0.0005 0.0005"/>
            </geometry>
            <material name="green"/>
        </visual>
	</link>

    <gazebo reference="camera_link">
        <material>Gazebo/Green</material>
    </gazebo>

    <joint name="head_camera_joint" type="fixed">
        <parent link="griper_link"/>
        <child link="camera_link"/>
        <origin xyz="0 0.057 0.0255" rpy="0 0 0"/>
    </joint>



<!--######################################################################-->
<joint name="arm_base_joint" type="continuous">
  <axis xyz="0 0 1"/>
  <parent link="world"/>
  <child link="arm_base"/>
  <origin rpy="0 0 0" xyz="0.0 0.0 0.1"/>
</joint>

<joint name="shoulder_joint" type="continuous">
  <axis xyz="0 1 0"/>
  <parent link="arm_base"/>
  <child link="bicep"/>
  <origin rpy="0 0 1.5708" xyz="-0.05166 0.0 0.20271"/>
</joint>

<joint name="bottom_wrist_joint" type="continuous">
  <axis xyz="0 1 0"/>
  <parent link="bicep"/>
  <child link="bottom_wrist"/>
  <origin rpy="0 0 0" xyz="0.0 -0.05194 0.269"/>
</joint>

<joint name="elbow_joint" type="continuous">
  <axis xyz="0 0 1"/>
  <parent link="bottom_wrist"/>
  <child link="elbow"/>
  <origin rpy="0 0 0" xyz="0.0 0 0.13522"/>
</joint>

<joint name="top_wrist_joint" type="continuous">
  <axis xyz="0 1 0"/>
  <parent link="elbow"/>
  <child link="top_wrist"/>
  <origin rpy="0 0 0" xyz="0.0 0 0.20994"/>
</joint>

<!--######################################################################-->
<transmission name="arm_base_trans" type="SimpleTransmission">
  <type>transmission_interface/SimpleTransmission</type>
  <actuator name="arm_base_motor">
   <hardwareInterface>hardware_interface/PositionJointInterface</hardwareInterface>
   <mechanicalReduction>1</mechanicalReduction>
  </actuator>
  <joint name="arm_base_joint">
   <hardwareInterface>hardware_interface/PositionJointInterface</hardwareInterface>
  </joint>
</transmission>

<transmission name="shoulder_trans" type="SimpleTransmission">
  <type>transmission_interface/SimpleTransmission</type>
  <actuator name="shoulder_motor">
   <hardwareInterface>hardware_interface/PositionJointInterface</hardwareInterface>
   <mechanicalReduction>1</mechanicalReduction>
  </actuator>
  <joint name="shoulder_joint">
   <hardwareInterface>hardware_interface/PositionJointInterface</hardwareInterface>
  </joint>
</transmission>

<transmission name="bottom_wrist_trans" type="SimpleTransmission">
  <type>transmission_interface/SimpleTransmission</type>
  <actuator name="bottom_wrist_motor">
   <hardwareInterface>hardware_interface/PositionJointInterface</hardwareInterface>
   <mechanicalReduction>1</mechanicalReduction>
  </actuator>
  <joint name="bottom_wrist_joint">
   <hardwareInterface>hardware_interface/PositionJointInterface</hardwareInterface>
  </joint>
</transmission>

<transmission name="elbow_trans" type="SimpleTransmission">
  <type>transmission_interface/SimpleTransmission</type>
  <actuator name="elbow_motor">
   <hardwareInterface>hardware_interface/PositionJointInterface</hardwareInterface>
   <mechanicalReduction>1</mechanicalReduction>
  </actuator>
  <joint name="elbow_joint">
   <hardwareInterface>hardware_interface/PositionJointInterface</hardwareInterface>
  </joint>
</transmission>

<transmission name="top_wrist_trans" type="SimpleTransmission">
  <type>transmission_interface/SimpleTransmission</type>
  <actuator name="top_wrist_motor">
   <hardwareInterface>hardware_interface/PositionJointInterface</hardwareInterface>
   <mechanicalReduction>1</mechanicalReduction>
  </actuator>
  <joint name="top_wrist_joint">
   <hardwareInterface>hardware_interface/PositionJointInterface</hardwareInterface>
  </joint>
</transmission>

<!--######################################################################-->
<gazebo>
    <plugin name="gazebo_ros_control" filename="libgazebo_ros_control.so">
      <robotNamespace>/</robotNamespace>
      <controlPeriod>0.001</controlPeriod>
      <legacyModeNS>false</legacyModeNS>
    </plugin>
  </gazebo>
<!--######################################################################-->
  <gazebo>
    <plugin name="joint_state_publisher" filename="libgazebo_ros_joint_state_publisher.so">
      <jointName>arm_base_joint, shoulder_joint, bottom_wrist_joint, elbow_joint, top_wrist_joint, finger_a_joint, finger_b_joint</jointName>
    </plugin>
  </gazebo>
<!--######################################################################-->

<!-- camera -->
  <gazebo reference="camera_link">
    <sensor type="camera" name="camera1">
      <update_rate>15.0</update_rate>
      <camera name="head">

          <pose>0 0 0 0 0 1.57</pose>

        <horizontal_fov>1.3962634</horizontal_fov>
        <image>
          <width>400</width>
          <height>400</height>
          <format>R8G8B8</format>
        </image>
        <clip>
          <near>0.01</near>
          <far>100</far>
        </clip>
        <noise>
          <type>gaussian</type>
          <stddev>0.007</stddev>
        </noise>
      </camera>
      <plugin name="camera_controller" filename="libgazebo_ros_camera.so">
        <alwaysOn>true</alwaysOn>
        <updateRate>0.0</updateRate>
        <cameraName>camera/camera1</cameraName>
        <imageTopicName>image_raw</imageTopicName>
        <cameraInfoTopicName>camera_info</cameraInfoTopicName>
        <frameName>camera_link</frameName>
        <hackBaseline>0.07</hackBaseline>
        <distortionK1>0.0</distortionK1>
        <distortionK2>0.0</distortionK2>
        <distortionK3>0.0</distortionK3>
        <distortionT1>0.0</distortionT1>
        <distortionT2>0.0</distortionT2>
      </plugin>
    </sensor>
  </gazebo>


</robot>